Workbook

Sheet Read me
A1: Project Atlas: integrated plan workbook
A2: HR policy and process documentation program
A4: Program dates: 2026-10-12 to 2027-10-08. Sponsor: Chief People Officer (CHRO). Program manager: HR Program Manager (PMO lead). Plan version 1.0.
A5: Exported from the Hire-to-Retire Atlas on 2026-10-01. The Atlas is the live source of truth for status and approvals; this workbook is a snapshot for planning and reporting.
A7: How to use it
A8: 1. Plan sheet: one row per item (57 policies, 97 processes, 284 legal obligations). Yellow columns are inputs: Status, Owner, Go-live override and Notes.
A9: 2. Go live (current) uses the override when one is entered, otherwise the planned date. Overdue and Days late are formulas against today's date.
A10: 3. Dashboard sheet: every number is a formula over the Plan sheet, so it updates as you change statuses.
A11: 4. Status values: Not started, Drafting, In review, Approved, Live, Not applicable. Approved, Live and Not applicable count as done.
A12: 5. Stage dates come from the plan: discover 2 weeks, draft 3, review 2, approve 2, go live 1, skipping the year-end freeze (Dec 21, 2026 to Jan 1, 2027).
A14: Waves
A15: Mobilize: 2026-10-12 to 2026-11-06. Team, charter, tooling, approval chains and a rated baseline of all 438 items.
... A22: POL-09 Anti-Harassment · Policy · Wave 1 · Governance, Ethics and Employee Relations · go live 29 Jan 2027 · Status: Drafting · Owner: Head of Employee Relations · Notes: Current doc on ER SharePoint; Israel bylaw and India IC addendum missing.

Sheet Dashboard
A1: Dashboard
A2: All figures are formulas over the Plan sheet.
A4: Items | B4: =COUNTA(Plan!$A$2:$A$439) -> 438
A5: Done (approved, live or not applicable) | B5: =COUNTIF(Plan!$P$2:$P$439,"Approved")+COUNTIF(Plan!$P$2:$P$439,"Live")+COUNTIF(Plan!$P$2:$P$439,"Not applicable") -> 0
A6: Percent done | B6: =IF(B4=0,0,B5/B4) -> 0
A7: Overdue | B7: =COUNTIF(Plan!$S$2:$S$439,"Overdue") -> 0
A8: Due so far | B8: =COUNTIF(Plan!$O$2:$O$439,"<"&TODAY()) -> 0
A9: Overdue as share of due | B9: =IF(B8=0,0,B7/B8) -> 0
A10: Calculated rating | B10: =IF(B9>=0.15,"Red",IF(B9>=0.05,"Amber","Green")) -> Green
A11: Rating thresholds | B11: Red at 15% or more of due items overdue, Amber at 5%. Set by the PMO; change here if the steering committee agrees different ones.
A13: By wave
A14: Wave | B14: Not started | C14: Drafting | D14: In review | E14: Approved | F14: Live | G14: Not applicable | H14: Total | I14: Done | J14: % done | K14: Overdue
A15: Wave 1 | B15: =COUNTIFS(Plan!$G$2:$G$439,$A15,Plan!$P$2:$P$439,"Not started") -> 170 | C15: =COUNTIFS(Plan!$G$2:$G$439,$A15,Plan!$P$2:$P$439,"Drafting") -> 0 | D15: =COUNTIFS(Plan!$G$2:$G$439,$A15,Plan!$P$2:$P$439,"In review") -> 0 | E15: =COUNTIFS(Plan!$G$2:$G$439,$A15,Plan!$P$2:$P$439,"Approved") -> 0 | F15: =COUNTIFS(Plan!$G$2:$G$439,$A15,Plan!$P$2:$P$439,"Live") -> 0 | G15: =COUNTIFS(Plan!$G$2:$G$439,$A15,Plan!$P$2:$P$439,"Not applicable") -> 0 | H15: =SUM(B15:G15) -> 170 | I15: =E15+F15+G15 -> 0 | J15: =IF(H15=0,0,I15/H15) -> 0 | K15: =COUNTIFS(Plan!$G$2:$G$439,$A15,Plan!$S$2:$S$439,"Overdue") -> 0
A16: Wave 2 | B16: =COUNTIFS(Plan!$G$2:$G$439,$A16,Plan!$P$2:$P$439,"Not started") -> 146 | C16: =COUNTIFS(Plan!$G$2:$G$439,$A16,Plan!$P$2:$P$439,"Drafting") -> 0 | D16: =COUNTIFS(Plan!$G$2:$G$439,$A16,Plan!$P$2:$P$439,"In review") -> 0 | E16: =COUNTIFS(Plan!$G$2:$G$439,$A16,Plan!$P$2:$P$439,"Approved") -> 0 | F16: =COUNTIFS(Plan!$G$2:$G$439,$A16,Plan!$P$2:$P$439,"Live") -> 0 | G16: =COUNTIFS(Plan!$G$2:$G$439,$A16,Plan!$P$2:$P$439,"Not applicable") -> 0 | H16: =SUM(B16:G16) -> 146 | I16: =E16+F16+G16 -> 0 | J16: =IF(H16=0,0,I16/H16) -> 0 | K16: =COUNTIFS(Plan!$G$2:$G$439,$A16,Plan!$S$2:$S$439,"Overdue") -> 0
A17: Wave 3 | B17: =COUNTIFS(Plan!$G$2:$G$439,$A17,Plan!$P$2:$P$439,"Not started") -> 105 | C17: =COUNTIFS(Plan!$G$2:$G$439,$A17,Plan!$P$2:$P$439,"Drafting") -> 0 | D17: =COUNTIFS(Plan!$G$2:$G$439,$A17,Plan!$P$2:$P$439,"In review") -> 0 | E17: =COUNTIFS(Plan!$G$2:$G$439,$A17,Plan!$P$2:$P$439,"Approved") -> 0 | F17: =COUNTIFS(Plan!$G$2:$G$439,$A17,Plan!$P$2:$P$439,"Live") -> 0 | G17: =COUNTIFS(Plan!$G$2:$G$439,$A17,Plan!$P$2:$P$439,"Not applicable") -> 0 | H17: =SUM(B17:G17) -> 105 | I17: =E17+F17+G17 -> 0 | J17: =IF(H17=0,0,I17/H17) -> 0 | K17: =COUNTIFS(Plan!$G$2:$G$439,$A17,Plan!$S$2:$S$439,"Overdue") -> 0
A18: Wave 4 | B18: =COUNTIFS(Plan!$G$2:$G$439,$A18,Plan!$P$2:$P$439,"Not started") -> 17 | C18: =COUNTIFS(Plan!$G$2:$G$439,$A18,Plan!$P$2:$P$439,"Drafting") -> 0 | D18: =COUNTIFS(Plan!$G$2:$G$439,$A18,Plan!$P$2:$P$439,"In review") -> 0 | E18: =COUNTIFS(Plan!$G$2:$G$439,$A18,Plan!$P$2:$P$439,"Approved") -> 0 | F18: =COUNTIFS(Plan!$G$2:$G$439,$A18,Plan!$P$2:$P$439,"Live") -> 0 | G18: =COUNTIFS(Plan!$G$2:$G$439,$A18,Plan!$P$2:$P$439,"Not applicable") -> 0 | H18: =SUM(B18:G18) -> 17 | I18: =E18+F18+G18 -> 0 | J18: =IF(H18=0,0,I18/H18) -> 0 | K18: =COUNTIFS(Plan!$G$2:$G$439,$A18,Plan!$S$2:$S$439,"Overdue") -> 0
A19: Total | B19: =SUM(B15:B18) -> 438 | C19: =SUM(C15:C18) -> 0 | D19: =SUM(D15:D18) -> 0 | E19: =SUM(E15:E18) -> 0 | F19: =SUM(F15:F18) -> 0 | G19: =SUM(G15:G18) -> 0 | H19: =SUM(H15:H18) -> 438 | I19: =SUM(I15:I18) -> 0 | J19: =IF(H19=0,0,I19/H19) -> 0 | K19: =SUM(K15:K18) -> 0
A21: By workstream
A22: Workstream | B22: Not started | C22: Drafting | D22: In review | E22: Approved | F22: Live | G22: Not applicable | H22: Total | I22: Done | J22: % done | K22: Overdue
A23: Governance, Ethics and Employee Relations | B23: =COUNTIFS(Plan!$F$2:$F$439,$A23,Plan!$P$2:$P$439,"Not started") -> 82 | C23: =COUNTIFS(Plan!$F$2:$F$439,$A23,Plan!$P$2:$P$439,"Drafting") -> 0 | D23: =COUNTIFS(Plan!$F$2:$F$439,$A23,Plan!$P$2:$P$439,"In review") -> 0 | E23: =COUNTIFS(Plan!$F$2:$F$439,$A23,Plan!$P$2:$P$439,"Approved") -> 0 | F23: =COUNTIFS(Plan!$F$2:$F$439,$A23,Plan!$P$2:$P$439,"Live") -> 0 | G23: =COUNTIFS(Plan!$F$2:$F$439,$A23,Plan!$P$2:$P$439,"Not applicable") -> 0 | H23: =SUM(B23:G23) -> 82 | I23: =E23+F23+G23 -> 0 | J23: =IF(H23=0,0,I23/H23) -> 0 | K23: =COUNTIFS(Plan!$F$2:$F$439,$A23,Plan!$S$2:$S$439,"Overdue") -> 0
A24: Talent Acquisition | B24: =COUNTIFS(Plan!$F$2:$F$439,$A24,Plan!$P$2:$P$439,"Not started") -> 43 | C24: =COUNTIFS(Plan!$F$2:$F$439,$A24,Plan!$P$2:$P$439,"Drafting") -> 0 | D24: =COUNTIFS(Plan!$F$2:$F$439,$A24,Plan!$P$2:$P$439,"In review") -> 0 | E24: =COUNTIFS(Plan!$F$2:$F$439,$A24,Plan!$P$2:$P$439,"Approved") -> 0 | F24: =COUNTIFS(Plan!$F$2:$F$439,$A24,Plan!$P$2:$P$439,"Live") -> 0 | G24: =COUNTIFS(Plan!$F$2:$F$439,$A24,Plan!$P$2:$P$439,"Not applicable") -> 0 | H24: =SUM(B24:G24) -> 43 | I24: =E24+F24+G24 -> 0 | J24: =IF(H24=0,0,I24/H24) -> 0 | K24: =COUNTIFS(Plan!$F$2:$F$439,$A24,Plan!$S$2:$S$439,"Overdue") -> 0
A25: HR Operations and Employee Lifecycle | B25: =COUNTIFS(Plan!$F$2:$F$439,$A25,Plan!$P$2:$P$439,"Not started") -> 75 | C25: =COUNTIFS(Plan!$F$2:$F$439,$A25,Plan!$P$2:$P$439,"Drafting") -> 0 | D25: =COUNTIFS(Plan!$F$2:$F$439,$A25,Plan!$P$2:$P$439,"In review") -> 0 | E25: =COUNTIFS(Plan!$F$2:$F$439,$A25,Plan!$P$2:$P$439,"Approved") -> 0 | F25: =COUNTIFS(Plan!$F$2:$F$439,$A25,Plan!$P$2:$P$439,"Live") -> 0 | G25: =COUNTIFS(Plan!$F$2:$F$439,$A25,Plan!$P$2:$P$439,"Not applicable") -> 0 | H25: =SUM(B25:G25) -> 75 | I25: =E25+F25+G25 -> 0 | J25: =IF(H25=0,0,I25/H25) -> 0 | K25: =COUNTIFS(Plan!$F$2:$F$439,$A25,Plan!$S$2:$S$439,"Overdue") -> 0
A26: Total Rewards and Payroll | B26: =COUNTIFS(Plan!$F$2:$F$439,$A26,Plan!$P$2:$P$439,"Not started") -> 111 | C26: =COUNTIFS(Plan!$F$2:$F$439,$A26,Plan!$P$2:$P$439,"Drafting") -> 0 | D26: =COUNTIFS(Plan!$F$2:$F$439,$A26,Plan!$P$2:$P$439,"In review") -> 0 | E26: =COUNTIFS(Plan!$F$2:$F$439,$A26,Plan!$P$2:$P$439,"Approved") -> 0 | F26: =COUNTIFS(Plan!$F$2:$F$439,$A26,Plan!$P$2:$P$439,"Live") -> 0 | G26: =COUNTIFS(Plan!$F$2:$F$439,$A26,Plan!$P$2:$P$439,"Not applicable") -> 0 | H26: =SUM(B26:G26) -> 111 | I26: =E26+F26+G26 -> 0 | J26: =IF(H26=0,0,I26/H26) -> 0 | K26: =COUNTIFS(Plan!$F$2:$F$439,$A26,Plan!$S$2:$S$439,"Overdue") -> 0
A27: Talent, Leave and Engagement | B27: =COUNTIFS(Plan!$F$2:$F$439,$A27,Plan!$P$2:$P$439,"Not started") -> 52 | C27: =COUNTIFS(Plan!$F$2:$F$439,$A27,Plan!$P$2:$P$439,"Drafting") -> 0 | D27: =COUNTIFS(Plan!$F$2:$F$439,$A27,Plan!$P$2:$P$439,"In review") -> 0 | E27: =COUNTIFS(Plan!$F$2:$F$439,$A27,Plan!$P$2:$P$439,"Approved") -> 0 | F27: =COUNTIFS(Plan!$F$2:$F$439,$A27,Plan!$P$2:$P$439,"Live") -> 0 | G27: =COUNTIFS(Plan!$F$2:$F$439,$A27,Plan!$P$2:$P$439,"Not applicable") -> 0 | H27: =SUM(B27:G27) -> 52 | I27: =E27+F27+G27 -> 0 | J27: =IF(H27=0,0,I27/H27) -> 0 | K27: =COUNTIFS(Plan!$F$2:$F$439,$A27,Plan!$S$2:$S$439,"Overdue") -> 0
A28: HR Data, Safety and Systems | B28: =COUNTIFS(Plan!$F$2:$F$439,$A28,Plan!$P$2:$P$439,"Not started") -> 75 | C28: =COUNTIFS(Plan!$F$2:$F$439,$A28,Plan!$P$2:$P$439,"Drafting") -> 0 | D28: =COUNTIFS(Plan!$F$2:$F$439,$A28,Plan!$P$2:$P$439,"In review") -> 0 | E28: =COUNTIFS(Plan!$F$2:$F$439,$A28,Plan!$P$2:$P$439,"Approved") -> 0 | F28: =COUNTIFS(Plan!$F$2:$F$439,$A28,Plan!$P$2:$P$439,"Live") -> 0 | G28: =COUNTIFS(Plan!$F$2:$F$439,$A28,Plan!$P$2:$P$439,"Not applicable") -> 0 | H28: =SUM(B28:G28) -> 75 | I28: =E28+F28+G28 -> 0 | J28: =IF(H28=0,0,I28/H28) -> 0 | K28: =COUNTIFS(Plan!$F$2:$F$439,$A28,Plan!$S$2:$S$439,"Overdue") -> 0
A29: Total | B29: =SUM(B23:B28) -> 438 | C29: =SUM(C23:C28) -> 0 | D29: =SUM(D23:D28) -> 0 | E29: =SUM(E23:E28) -> 0 | F29: =SUM(F23:F28) -> 0 | G29: =SUM(G23:G28) -> 0 | H29: =SUM(H23:H28) -> 438 | I29: =SUM(I23:I28) -> 0 | J29: =IF(H29=0,0,I29/H29) -> 0 | K29: =SUM(K23:K28) -> 0
A31: By type
A32: Type | B32: Not started | C32: Drafting | D32: In review | E32: Approved | F32: Live | G32: Not applicable | H32: Total | I32: Done | J32: % done | K32: Overdue
A33: Policy | B33: =COUNTIFS(Plan!$C$2:$C$439,$A33,Plan!$P$2:$P$439,"Not started") -> 57 | C33: =COUNTIFS(Plan!$C$2:$C$439,$A33,Plan!$P$2:$P$439,"Drafting") -> 0 | D33: =COUNTIFS(Plan!$C$2:$C$439,$A33,Plan!$P$2:$P$439,"In review") -> 0 | E33: =COUNTIFS(Plan!$C$2:$C$439,$A33,Plan!$P$2:$P$439,"Approved") -> 0 | F33: =COUNTIFS(Plan!$C$2:$C$439,$A33,Plan!$P$2:$P$439,"Live") -> 0 | G33: =COUNTIFS(Plan!$C$2:$C$439,$A33,Plan!$P$2:$P$439,"Not applicable") -> 0 | H33: =SUM(B33:G33) -> 57 | I33: =E33+F33+G33 -> 0 | J33: =IF(H33=0,0,I33/H33) -> 0 | K33: =COUNTIFS(Plan!$C$2:$C$439,$A33,Plan!$S$2:$S$439,"Overdue") -> 0
A34: Process | B34: =COUNTIFS(Plan!$C$2:$C$439,$A34,Plan!$P$2:$P$439,"Not started") -> 97 | C34: =COUNTIFS(Plan!$C$2:$C$439,$A34,Plan!$P$2:$P$439,"Drafting") -> 0 | D34: =COUNTIFS(Plan!$C$2:$C$439,$A34,Plan!$P$2:$P$439,"In review") -> 0 | E34: =COUNTIFS(Plan!$C$2:$C$439,$A34,Plan!$P$2:$P$439,"Approved") -> 0 | F34: =COUNTIFS(Plan!$C$2:$C$439,$A34,Plan!$P$2:$P$439,"Live") -> 0 | G34: =COUNTIFS(Plan!$C$2:$C$439,$A34,Plan!$P$2:$P$439,"Not applicable") -> 0 | H34: =SUM(B34:G34) -> 97 | I34: =E34+F34+G34 -> 0 | J34: =IF(H34=0,0,I34/H34) -> 0 | K34: =COUNTIFS(Plan!$C$2:$C$439,$A34,Plan!$S$2:$S$439,"Overdue") -> 0
A35: Filing | B35: =COUNTIFS(Plan!$C$2:$C$439,$A35,Plan!$P$2:$P$439,"Not started") -> 82 | C35: =COUNTIFS(Plan!$C$2:$C$439,$A35,Plan!$P$2:$P$439,"Drafting") -> 0 | D35: =COUNTIFS(Plan!$C$2:$C$439,$A35,Plan!$P$2:$P$439,"In review") -> 0 | E35: =COUNTIFS(Plan!$C$2:$C$439,$A35,Plan!$P$2:$P$439,"Approved") -> 0 | F35: =COUNTIFS(Plan!$C$2:$C$439,$A35,Plan!$P$2:$P$439,"Live") -> 0 | G35: =COUNTIFS(Plan!$C$2:$C$439,$A35,Plan!$P$2:$P$439,"Not applicable") -> 0 | H35: =SUM(B35:G35) -> 82 | I35: =E35+F35+G35 -> 0 | J35: =IF(H35=0,0,I35/H35) -> 0 | K35: =COUNTIFS(Plan!$C$2:$C$439,$A35,Plan!$S$2:$S$439,"Overdue") -> 0
A36: Control | B36: =COUNTIFS(Plan!$C$2:$C$439,$A36,Plan!$P$2:$P$439,"Not started") -> 79 | C36: =COUNTIFS(Plan!$C$2:$C$439,$A36,Plan!$P$2:$P$439,"Drafting") -> 0 | D36: =COUNTIFS(Plan!$C$2:$C$439,$A36,Plan!$P$2:$P$439,"In review") -> 0 | E36: =COUNTIFS(Plan!$C$2:$C$439,$A36,Plan!$P$2:$P$439,"Approved") -> 0 | F36: =COUNTIFS(Plan!$C$2:$C$439,$A36,Plan!$P$2:$P$439,"Live") -> 0 | G36: =COUNTIFS(Plan!$C$2:$C$439,$A36,Plan!$P$2:$P$439,"Not applicable") -> 0 | H36: =SUM(B36:G36) -> 79 | I36: =E36+F36+G36 -> 0 | J36: =IF(H36=0,0,I36/H36) -> 0 | K36: =COUNTIFS(Plan!$C$2:$C$439,$A36,Plan!$S$2:$S$439,"Overdue") -> 0
A37: Program | B37: =COUNTIFS(Plan!$C$2:$C$439,$A37,Plan!$P$2:$P$439,"Not started") -> 45 | C37: =COUNTIFS(Plan!$C$2:$C$439,$A37,Plan!$P$2:$P$439,"Drafting") -> 0 | D37: =COUNTIFS(Plan!$C$2:$C$439,$A37,Plan!$P$2:$P$439,"In review") -> 0 | E37: =COUNTIFS(Plan!$C$2:$C$439,$A37,Plan!$P$2:$P$439,"Approved") -> 0 | F37: =COUNTIFS(Plan!$C$2:$C$439,$A37,Plan!$P$2:$P$439,"Live") -> 0 | G37: =COUNTIFS(Plan!$C$2:$C$439,$A37,Plan!$P$2:$P$439,"Not applicable") -> 0 | H37: =SUM(B37:G37) -> 45 | I37: =E37+F37+G37 -> 0 | J37: =IF(H37=0,0,I37/H37) -> 0 | K37: =COUNTIFS(Plan!$C$2:$C$439,$A37,Plan!$S$2:$S$439,"Overdue") -> 0
A38: Notice | B38: =COUNTIFS(Plan!$C$2:$C$439,$A38,Plan!$P$2:$P$439,"Not started") -> 40 | C38: =COUNTIFS(Plan!$C$2:$C$439,$A38,Plan!$P$2:$P$439,"Drafting") -> 0 | D38: =COUNTIFS(Plan!$C$2:$C$439,$A38,Plan!$P$2:$P$439,"In review") -> 0 | E38: =COUNTIFS(Plan!$C$2:$C$439,$A38,Plan!$P$2:$P$439,"Approved") -> 0 | F38: =COUNTIFS(Plan!$C$2:$C$439,$A38,Plan!$P$2:$P$439,"Live") -> 0 | G38: =COUNTIFS(Plan!$C$2:$C$439,$A38,Plan!$P$2:$P$439,"Not applicable") -> 0 | H38: =SUM(B38:G38) -> 40 | I38: =E38+F38+G38 -> 0 | J38: =IF(H38=0,0,I38/H38) -> 0 | K38: =COUNTIFS(Plan!$C$2:$C$439,$A38,Plan!$S$2:$S$439,"Overdue") -> 0
A39: Record | B39: =COUNTIFS(Plan!$C$2:$C$439,$A39,Plan!$P$2:$P$439,"Not started") -> 17 | C39: =COUNTIFS(Plan!$C$2:$C$439,$A39,Plan!$P$2:$P$439,"Drafting") -> 0 | D39: =COUNTIFS(Plan!$C$2:$C$439,$A39,Plan!$P$2:$P$439,"In review") -> 0 | E39: =COUNTIFS(Plan!$C$2:$C$439,$A39,Plan!$P$2:$P$439,"Approved") -> 0 | F39: =COUNTIFS(Plan!$C$2:$C$439,$A39,Plan!$P$2:$P$439,"Live") -> 0 | G39: =COUNTIFS(Plan!$C$2:$C$439,$A39,Plan!$P$2:$P$439,"Not applicable") -> 0 | H39: =SUM(B39:G39) -> 17 | I39: =E39+F39+G39 -> 0 | J39: =IF(H39=0,0,I39/H39) -> 0 | K39: =COUNTIFS(Plan!$C$2:$C$439,$A39,Plan!$S$2:$S$439,"Overdue") -> 0
A40: Committee | B40: =COUNTIFS(Plan!$C$2:$C$439,$A40,Plan!$P$2:$P$439,"Not started") -> 13 | C40: =COUNTIFS(Plan!$C$2:$C$439,$A40,Plan!$P$2:$P$439,"Drafting") -> 0 | D40: =COUNTIFS(Plan!$C$2:$C$439,$A40,Plan!$P$2:$P$439,"In review") -> 0 | E40: =COUNTIFS(Plan!$C$2:$C$439,$A40,Plan!$P$2:$P$439,"Approved") -> 0 | F40: =COUNTIFS(Plan!$C$2:$C$439,$A40,Plan!$P$2:$P$439,"Live") -> 0 | G40: =COUNTIFS(Plan!$C$2:$C$439,$A40,Plan!$P$2:$P$439,"Not applicable") -> 0 | H40: =SUM(B40:G40) -> 13 | I40: =E40+F40+G40 -> 0 | J40: =IF(H40=0,0,I40/H40) -> 0 | K40: =COUNTIFS(Plan!$C$2:$C$439,$A40,Plan!$S$2:$S$439,"Overdue") -> 0
A41: Training | B41: =COUNTIFS(Plan!$C$2:$C$439,$A41,Plan!$P$2:$P$439,"Not started") -> 8 | C41: =COUNTIFS(Plan!$C$2:$C$439,$A41,Plan!$P$2:$P$439,"Drafting") -> 0 | D41: =COUNTIFS(Plan!$C$2:$C$439,$A41,Plan!$P$2:$P$439,"In review") -> 0 | E41: =COUNTIFS(Plan!$C$2:$C$439,$A41,Plan!$P$2:$P$439,"Approved") -> 0 | F41: =COUNTIFS(Plan!$C$2:$C$439,$A41,Plan!$P$2:$P$439,"Live") -> 0 | G41: =COUNTIFS(Plan!$C$2:$C$439,$A41,Plan!$P$2:$P$439,"Not applicable") -> 0 | H41: =SUM(B41:G41) -> 8 | I41: =E41+F41+G41 -> 0 | J41: =IF(H41=0,0,I41/H41) -> 0 | K41: =COUNTIFS(Plan!$C$2:$C$439,$A41,Plan!$S$2:$S$439,"Overdue") -> 0
A42: Total | B42: =SUM(B33:B41) -> 438 | C42: =SUM(C33:C41) -> 0 | D42: =SUM(D33:D41) -> 0 | E42: =SUM(E33:E41) -> 0 | F42: =SUM(F33:F41) -> 0 | G42: =SUM(G33:G41) -> 0 | H42: =SUM(H33:H41) -> 438 | I42: =SUM(I33:I41) -> 0 | J42: =IF(H42=0,0,I42/H42) -> 0 | K42: =SUM(K33:K41) -> 0

Sheet Plan
A1: ID | B1: Item | C1: Type | D1: Domain | E1: Tier | F1: Workstream | G1: Wave | H1: Start | I1: Discover done | J1: Draft done | K1: Review done | L1: Approved by | M1: Go live (plan) | N1: Go live (override) | O1: Go live (current) | P1: Status | Q1: Owner | R1: Notes | S1: Overdue | T1: Days late
A2: POL-01 | B2: Code of Business Conduct & Ethics | C2: Policy | D2: Governance | E2: Public-company driven | F2: Governance, Ethics and Employee Relations | G2: Wave 1 | H2: 46335 | I2: 46346 | J2: 46367 | K2: 46395 | L2: 46409 | M2: 46416 | O2: =IF(N2<>"",N2,M2) -> 46416 | P2: Not started | Q2: Ethics & Compliance (Chief Compliance Officer); HR Employee Relations for people-related sections | S2: =IF(AND(O2<TODAY(),P2<>"Approved",P2<>"Live",P2<>"Not applicable"),"Overdue","") | T2: =IF(S2="Overdue",TODAY()-O2,"")
A3: POL-02 | B3: Speak Up & Non-Retaliation | C3: Policy | D3: Governance | E3: Public-company driven | F3: Governance, Ethics and Employee Relations | G3: Wave 1 | H3: 46335 | I3: 46346 | J3: 46367 | K3: 46395 | L3: 46409 | M3: 46416 | O3: =IF(N3<>"",N3,M3) -> 46416 | P3: Not started | Q3: Ethics & Compliance (hotline and case management); Employee Relations for people-related investigations | S3: =IF(AND(O3<TODAY(),P3<>"Approved",P3<>"Live",P3<>"Not applicable"),"Overdue","") | T3: =IF(S3="Overdue",TODAY()-O3,"")
A4: POL-03 | B4: Conflicts of Interest & Outside Activities | C4: Policy | D4: Governance | E4: Public-company driven | F4: Governance, Ethics and Employee Relations | G4: Wave 1 | H4: 46335 | I4: 46346 | J4: 46367 | K4: 46395 | L4: 46409 | M4: 46416 | O4: =IF(N4<>"",N4,M4) -> 46416 | P4: Not started | Q4: Ethics & Compliance (disclosure program), with Legal (related-person transactions) and HR (outside-employment approvals) | S4: =IF(AND(O4<TODAY(),P4<>"Approved",P4<>"Live",P4<>"Not applicable"),"Overdue","") | T4: =IF(S4="Overdue",TODAY()-O4,"")
A5: POL-04 | B5: Anti-Bribery & Anti-Corruption (HR aspects) | C5: Policy | D5: Governance | E5: Public-company driven | F5: Governance, Ethics and Employee Relations | G5: Wave 1 | H5: 46335 | I5: 46346 | J5: 46367 | K5: 46395 | L5: 46409 | M5: 46416 | O5: =IF(N5<>"",N5,M5) -> 46416 | P5: Not started | Q5: Ethics & Compliance (ABAC program); Talent Acquisition and Employee Relations own the HR controls | S5: =IF(AND(O5<TODAY(),P5<>"Approved",P5<>"Live",P5<>"Not applicable"),"Overdue","") | T5: =IF(S5="Overdue",TODAY()-O5,"")
A6: POL-05 | B6: Insider Trading | C6: Policy | D6: Governance | E6: Public-company driven | F6: Governance, Ethics and Employee Relations | G6: Wave 1 | H6: 46335 | I6: 46346 | J6: 46367 | K6: 46395 | L6: 46409 | M6: 46416 | O6: =IF(N6<>"",N6,M6) -> 46416 | P6: Not started | Q6: Legal (Securities) with Equity Administration (Stock Admin) | S6: =IF(AND(O6<TODAY(),P6<>"Approved",P6<>"Live",P6<>"Not applicable"),"Overdue","") | T6: =IF(S6="Overdue",TODAY()-O6,"")
A7: POL-06 | B7: Compensation Recovery (Clawback) | C7: Policy | D7: Governance | E7: Public-company driven | F7: Governance, Ethics and Employee Relations | G7: Wave 1 | H7: 46335 | I7: 46346 | J7: 46367 | K7: 46395 | L7: 46409 | M7: 46416 | O7: =IF(N7<>"",N7,M7) -> 46416 | P7: Not started | Q7: Total Rewards with Legal and Finance (Controller) | S7: =IF(AND(O7<TODAY(),P7<>"Approved",P7<>"Live",P7<>"Not applicable"),"Overdue","") | T7: =IF(S7="Overdue",TODAY()-O7,"")
A8: POL-08 | B8: Equal Employment Opportunity | C8: Policy | D8: Relations | E8: Legally required | F8: Governance, Ethics and Employee Relations | G8: Wave 1 | H8: 46335 | I8: 46346 | J8: 46367 | K8: 46395 | L8: 46409 | M8: 46416 | O8: =IF(N8<>"",N8,M8) -> 46416 | P8: Not started | Q8: HR (Employee Relations) with Employment Legal; Talent Acquisition for hiring practices | S8: =IF(AND(O8<TODAY(),P8<>"Approved",P8<>"Live",P8<>"Not applicable"),"Overdue","") | T8: =IF(S8="Overdue",TODAY()-O8,"")
A9: POL-09 | B9: Anti-Harassment | C9: Policy | D9: Relations | E9: Legally required | F9: Governance, Ethics and Employee Relations | G9: Wave 1 | H9: 46335 | I9: 46346 | J9: 46367 | K9: 46395 | L9: 46409 | M9: 46416 | O9: =IF(N9<>"",N9,M9) -> 46416 | P9: Not started | Q9: HR (Employee Relations) | S9: =IF(AND(O9<TODAY(),P9<>"Approved",P9<>"Live",P9<>"Not applicable"),"Overdue","") | T9: =IF(S9="Overdue",TODAY()-O9,"")
A10: POL-16 | B10: Recruitment & Selection | C10: Policy | D10: Recruit | E10: Legally required | F10: Talent Acquisition | G10: Wave 1 | H10: 46335 | I10: 46346 | J10: 46367 | K10: 46395 | L10: 46409 | M10: 46416 | O10: =IF(N10<>"",N10,M10) -> 46416 | P10: Not started | Q10: Talent Acquisition (Head of TA) | S10: =IF(AND(O10<TODAY(),P10<>"Approved",P10<>"Live",P10<>"Not applicable"),"Overdue","") | T10: =IF(S10="Overdue",TODAY()-O10,"")
A11: POL-17 | B11: Background Screening | C11: Policy | D11: Recruit | E11: Legally required | F11: Talent Acquisition | G11: Wave 1 | H11: 46335 | I11: 46346 | J11: 46367 | K11: 46395 | L11: 46409 | M11: 46416 | O11: =IF(N11<>"",N11,M11) -> 46416 | P11: Not started | Q11: Talent Acquisition Operations with Legal (Employment and Privacy) and Security | S11: =IF(AND(O11<TODAY(),P11<>"Approved",P11<>"Live",P11<>"Not applicable"),"Overdue","") | T11: =IF(S11="Overdue",TODAY()-O11,"")
A12: POL-18 | B12: Export Control & Deemed Exports (Employees) | C12: Policy | D12: Recruit | E12: Semiconductor-specific | F12: Talent Acquisition | G12: Wave 1 | H12: 46335 | I12: 46346 | J12: 46367 | K12: 46395 | L12: 46409 | M12: 46416 | O12: =IF(N12<>"",N12,M12) -> 46416 | P12: Not started | Q12: Trade Compliance (Export Control Officer) with HR (People Ops, Talent Acquisition, Immigration) and IT/Security | S12: =IF(AND(O12<TODAY(),P12<>"Approved",P12<>"Live",P12<>"Not applicable"),"Overdue","") | T12: =IF(S12="Overdue",TODAY()-O12,"")
A13: POL-19 | B13: Immigration Sponsorship | C13: Policy | D13: Recruit | E13: Legally required | F13: Talent Acquisition | G13: Wave 1 | H13: 46335 | I13: 46346 | J13: 46367 | K13: 46395 | L13: 46409 | M13: 46416 | O13: =IF(N13<>"",N13,M13) -> 46416 | P13: Not started | Q13: Immigration (Global Mobility) with Talent Acquisition and Legal | S13: =IF(AND(O13<TODAY(),P13<>"Approved",P13<>"Live",P13<>"Not applicable"),"Overdue","") | T13: =IF(S13="Overdue",TODAY()-O13,"")
... A439: R-USTX-18 | B439: Texas restrictive covenant program | C439: Program | D439: Offboard | E439: Best practice | F439: HR Operations and Employee Lifecycle | G439: Wave 4 | H439: 46629 | I439: 46633 | J439: 46647 | K439: 46654 | L439: 46661 | M439: 46668 | O439: =IF(N439<>"",N439,M439) -> 46668 | P439: Not started | Q439: Employment Legal + Total Rewards + HRBPs | S439: =IF(AND(O439<TODAY(),P439<>"Approved",P439<>"Live",P439<>"Not applicable"),"Overdue","") | T439: =IF(S439="Overdue",TODAY()-O439,"")

Sheet Milestones
A1: ID | B1: Date | C1: Milestone | D1: Wave | E1: Type | F1: Done when
A2: M01 | B2: 46307 | C2: Project kickoff | D2: W0 | E2: event | F2: Kickoff held with sponsor, workstream leads, regional HR leads and Legal.
A3: M02 | B3: 46318 | C3: Charter approved | D3: W0 | E3: gate | F3: Steering committee approves charter, scope, resourcing and governance.
A4: M03 | B4: 46325 | C4: Approval chains configured | D4: W0 | E4: deliverable | F4: Every chain has named approvers; test submission run end to end.
A5: M04 | B5: 46332 | C5: Baseline complete and Mobilize gate | D5: W0 | E5: gate | F5: All 438 items have an owner, a current-state rating and a wave; plan v1.0 baselined.
A6: M05 | B6: 46335 | C6: Wave 1 starts | D6: W1 | E6: event | F6: Wave 1 items in Discover; workshops scheduled.
A7: M06 | B7: 46374 | C7: Wave 1 drafts complete | D7: W1 | E7: deliverable | F7: All Wave 1 drafts submitted for review before the year-end freeze.
A8: M07 | B8: 46416 | C8: Wave 1 approvals complete | D8: W1 | E8: gate | F8: Every Wave 1 approval chain closed; works council consultations started where required.
A9: M08 | B9: 46430 | C9: Wave 1 live | D9: W1 | E9: gate | F9: Wave 1 published, communicated and evidenced; wave retrospective held.
A10: M09 | B10: 46433 | C10: Wave 2 starts | D10: W2 | E10: event | F10: Wave 2 items in Discover.
A11: M10 | B11: 46486 | C11: Wave 2 drafts complete | D11: W2 | E11: deliverable | F11: All Wave 2 drafts submitted for review.
A12: M11 | B12: 46521 | C12: Wave 2 live | D12: W2 | E12: gate | F12: Wave 2 published, communicated and evidenced.
A13: M12 | B13: 46524 | C13: Wave 3 starts | D13: W3 | E13: event | F13: Wave 3 items in Discover.
... A19: M18 | B19: 46668 | C19: Project close | D19: W4 | E19: gate | F19: Close-out report and lessons learned approved by the steering committee.

Sheet Risks
A1: ID | B1: Risk | C1: Detail | D1: Likelihood | E1: Impact | F1: Score | G1: Owner | H1: Mitigation | I1: Trigger | J1: Status
A2: R01 | B2: Germany works council co-determination delays | C2: Where a works council exists at a German establishment, policies on conduct rules (BetrVG §87(1) no.1), working time (nos.2-3), technical tools able to monitor behaviour or performance such as the HRIS, M365 and DLP (no.6), pay and bonus principles (nos.10-11), mobile work (no.14) and health protection must be adopted as works agreements. The council can enjoin a unilateral rollout, and an unresolved dispute goes to the Einigungsstelle, which can push German effective dates months past the global date. | D2: Medium | E2: High | F2: =(MATCH(D2,{"Low","Medium","High"},0))*(MATCH(E2,{"Low","Medium","High"},0)) -> 6 | G2: Regional HR lead (EMEA) | H2: Confirm by 30 Oct 2026 whether a works council exists at each German establishment. Tag every co-determined item in Atlas at Discover. Brief the council on the Atlas scope in November, group co-determined topics into one framework works agreement with annexes, and open consultation on Wave 1 items by 29 Jan 2027 (M07). Publish global policies with a German addendum that names the sections applying only once the works agreement is signed. | I2: No agreement in principle 6 weeks after consultation opens, or the council asks for the Einigungsstelle. | J2: Open
A3: R02 | B3: China democratic procedure not completed or not evidenced | C3: Rules on pay, hours, leave, safety, discipline and training must be discussed with the employee congress or all employees, finalised after consultation with the union or employee representatives and publicised with signed acknowledgment (Labor Contract Law Art. 4). If a step is skipped or the records are missing, the handbook cannot support an Art. 39 dismissal. The Lunar New Year freeze (5 to 14 Feb 2027) removes the last two weeks of Wave 1. | D3: Medium | E3: High | F3: =(MATCH(D3,{"Low","Medium","High"},0))*(MATCH(E3,{"Low","Medium","High"},0)) -> 6 | G3: Country HR lead, China | H3: Run one consolidated democratic procedure per wave covering Shanghai and Shenzhen, not one per policy. Use a bilingual handbook with Chinese prevailing. Hold the Wave 1 procedure from 6 to 29 Jan 2027 and publish after the freeze. File meeting notices, sign-in sheets, the comment log, consultation minutes and signed acknowledgments in Atlas before the item can move to Go live. | I3: A China item reaches Approve without consultation records, or acknowledgment is below 95% two weeks after publication. | J3: Open
A4: R03 | B4: Vietnam internal labour regulations registration delays | C4: Rules on working time, discipline, sexual harassment, protection of secrets and material liability bind employees only once they sit in internal labour regulations (ILR) that were consulted with the grassroots union, registered with the provincial Department of Home Affairs within 10 days of issue and posted at the workplace. ILR take effect 15 days after the authority receives a complete dossier, and discipline is valid only on registered grounds. An incomplete dossier restarts the clock. | D4: Medium | E4: High | F4: =(MATCH(D4,{"Low","Medium","High"},0))*(MATCH(E4,{"Low","Medium","High"},0)) -> 6 | G4: Country HR lead, Vietnam | H4: Batch ILR changes into one registration per wave. Have local counsel pre-check the Vietnamese dossier before submission. Keep the current registered ILR in force until the new version takes effect, and schedule union consultation and submission outside the Tet freeze (5 to 14 Feb 2027). | I4: Dossier returned as incomplete, or no proof of receipt within 10 working days of submission. | J4: Open
A5: R04 | B5: Taiwan work rules filing and approval | C5: With 30 or more employees, work rules must be submitted to the local labor authority (the Science Park Bureau for Hsinchu Science Park sites) for approval, posted, and refiled on every amendment. Global policies are not enforceable locally unless they are incorporated. Overtime and flexible-hours changes also need consent at the quarterly labor-management meeting, so authority comments or a missed meeting can hold Taiwan launches past the wave date. | D5: Medium | E5: Medium | F5: =(MATCH(D5,{"Low","Medium","High"},0))*(MATCH(E5,{"Low","Medium","High"},0)) -> 4 | G5: Country HR lead, Taiwan | H5: Map each global policy to a work-rule chapter at Discover. File one consolidated Traditional Chinese amendment per wave, timed to the quarterly labor-management meeting. Ask local counsel to pre-review each filing, and keep the approved work rules as the local source of truth until the amendment is approved. | I5: The authority asks for revisions, or approval has not arrived 8 weeks after filing. | J5: Open
A6: R05 | B6: Translation quality and lead time | C6: Local versions are needed in at least German, Hebrew, Simplified Chinese, Traditional Chinese, Vietnamese, Kannada, Telugu and Spanish. In China, Taiwan and Vietnam the local text is what authorities and courts rely on. Translating drafts that later change, or using translators without HR and legal terminology, creates rework and legal exposure. | D6: High | E6: Medium | F6: =(MATCH(D6,{"Low","Medium","High"},0))*(MATCH(E6,{"Low","Medium","High"},0)) -> 6 | G6: HR Change and Communications lead | H6: Translate only after Legal review (policy chain step s3) is complete. Use one vendor with an HR and legal glossary and translation memory, and require in-country review by the Country HR lead within 5 business days. Plan 10 business days per batch and send batches weekly. | I6: More than 10% of translated documents come back with substantive errors, or a batch takes more than 10 business days. | J6: Open
A7: R06 | B7: Legal review bottleneck | C7: Employment counsel reviews every policy (policy chain step s3) and every legal obligation (obligation chain step s2). Wave 1 drafts all arrive before 18 Dec 2026, so the review queue peaks around the year-end freeze, when local counsel are also slow to respond. | D7: High | E7: High | F7: =(MATCH(D7,{"Low","Medium","High"},0))*(MATCH(E7,{"Low","Medium","High"},0)) -> 9 | G7: Employment counsel | H7: Tier reviews by risk so process documents without legal content get a light review. Build a clause library for repeated text (non-retaliation, NLRA savings clause, whistleblower carve-outs, privacy notices). Engage a local counsel panel on fixed-fee bundles per country. Set a 5-business-day review target and publish queue age in the weekly PMO status report. | I7: More than 40 items waiting for Legal review, or a median wait above 7 business days for two weeks in a row. | J7: Open
A8: R07 | B8: SME availability during year-end, SOX testing and the annual cycle | C8: Payroll, Stock Administration, Total Rewards and HRIS experts carry year-end payroll, W-2 and tax-year changes, Q4 SOX testing, the 10-K and the annual compensation cycle between December and March. Wave 1 drafting and approval fall in the same window. | D8: High | E8: Medium | F8: =(MATCH(D8,{"Low","Medium","High"},0))*(MATCH(E8,{"Low","Medium","High"},0)) -> 6 | G8: Head of Total Rewards | H8: Run WS4 and WS6 Discover workshops in November. Keep payroll and stock administration experts off Atlas drafting from 14 Dec 2026 to 29 Jan 2027 except for approvals. Agree backfill or contract writers for documentation, and move lower-risk WS4 items to Wave 2. | I8: More than 20% of scheduled SME workshops in a month are cancelled or moved. | J8: Open
A9: R08 | B9: Holiday freezes compress Wave 1 | C9: The year-end freeze (21 Dec 2026 to 1 Jan 2027) allows no approvals or launches, and the Lunar New Year and Tet freeze (5 to 14 Feb 2027) covers the last two weeks before Wave 1 goes live on 12 Feb 2027. Any slip in December drafts pushes approvals into late January with no slack. | D9: High | E9: Medium | F9: =(MATCH(D9,{"Low","Medium","High"},0))*(MATCH(E9,{"Low","Medium","High"},0)) -> 6 | G9: HR Program Manager | H9: Hold the 18 Dec 2026 draft deadline (M06) and run a readiness check on 11 Dec. Book approver time in the first two weeks of January. Set China, Taiwan and Vietnam local effective dates after the Lunar New Year freeze from the start, so the 12 Feb milestone covers only global publication for those countries. | I9: More than 15% of Wave 1 drafts not submitted by 18 Dec 2026. | J9: Open
A10: R09 | B10: Approver turnover or unavailability | C10: Each chain step is held by a role. If an approver leaves, changes role or goes on leave, items stall, especially at steps with the 'all' rule such as Regional HR review in the policy chain, where all three regions must sign. | D10: Medium | E10: Medium | F10: =(MATCH(D10,{"Low","Medium","High"},0))*(MATCH(E10,{"Low","Medium","High"},0)) -> 4 | G10: HR Program Manager | H10: Name a primary and a delegate for every chain step. Reconcile the approver roster with HRIS org data monthly. Escalate any step idle for 5 business days to the workstream lead, then to the steering committee. | I10: An approval step is idle for more than 5 business days, or an approver's HRIS record shows a role change, leave or termination. | J10: Open
A11: R10 | B11: Scope creep from new laws | C11: Laws taking effect during the program will change items already in flight, for example California CCPA automated decision-making duties (1 Jan 2027), Colorado SB 26-189 AI notices (1 Jan 2027, replacing SB 24-205), India DPDP notice and consent duties (13 May 2027), the Washington noncompete ban (30 June 2027), California SB 947 (1 Jul 2027 if signed), Texas laws from the 2027 session (usually effective 1 Sep 2027) and German transposition of the EU Pay Transparency Directive, which missed the 7 June 2026 deadline with a bill expected in early 2027. | D11: High | E11: Medium | F11: =(MATCH(D11,{"Low","Medium","High"},0))*(MATCH(E11,{"Low","Medium","High"},0)) -> 6 | G11: Employment counsel | H11: Run a monthly legal change scan against the library watchlists. Add or reopen items only through a change request decided by the steering committee. Hold about 10% of Wave 3 and Wave 4 capacity for law changes, and give every item a review date so later changes go to business-as-usual owners. | I11: A new law or rule with an effective date before 8 Oct 2027 affects a live or in-flight item. | J11: Open
A12: R11 | B12: Inconsistent current-state documents | C12: Existing policies sit in several places (intranet pages, the HRIS document library, country shared drives, offer and handbook templates), often in conflicting versions. Owners may draft from an out-of-date source, and old copies left online contradict the approved version. | D12: High | E12: Medium | F12: =(MATCH(D12,{"Low","Medium","High"},0))*(MATCH(E12,{"Low","Medium","High"},0)) -> 6 | G12: Workstream leads | H12: At Discover, collect every version and record the source of truth in Atlas. Rate each item's current state on the standard scale. At Go live, retire or redirect superseded copies and file the retirement as evidence. | I12: More than 25% of Wave 1 items are rated as having conflicting current documents at Discover. | J12: Open
A13: R12 | B13: HRIS (Darwinbox) configuration dependencies | C13: Changes to leave, attendance, time recording, probation, letters and acknowledgments need Darwinbox configuration before a policy or process can go live. HRIS release windows and testing are not in the Atlas stage durations, and in Germany a change to a system able to monitor behaviour or performance may itself need a works agreement. | D13: Medium | E13: High | F13: =(MATCH(D13,{"Low","Medium","High"},0))*(MATCH(E13,{"Low","Medium","High"},0)) -> 6 | G13: Director, HRIS and People Analytics | H13: Flag 'system change needed' at Discover and open the HRIS ticket during Draft. Keep a joint backlog and align effective dates to the HRIS release calendar. Use the process chain publish step (s4) to confirm systems are ready before approval. | I13: An item reaches Approve with an HRIS ticket not scheduled before its planned effective date. | J13: Open
... A24: R23 | B24: Low adoption of Atlas by contributors | C24: If owners keep drafting in email and local files, Atlas status will be wrong, approvals will happen outside the chains and evidence will be missing at audit. | D24: Medium | E24: Medium | F24: =(MATCH(D24,{"Low","Medium","High"},0))*(MATCH(E24,{"Low","Medium","High"},0)) -> 4 | G24: HR Program Manager | H24: Make Atlas the only route to approval, with no sign-off by email. Train owners with V2 and V3 before Wave 1, hold weekly office hours and report each workstream's Atlas activity at status meetings. | I24: More than 20% of in-flight items show no Atlas activity for three weeks. | J24: Open
A26: Score = likelihood (1 low, 2 medium, 3 high) x impact (same scale). 6 or more is a high risk on the dashboard and status report.

Sheet Issues
A1: ID | B1: Issue | C1: Detail | D1: Priority | E1: Owner | F1: Action | G1: Due | H1: Status
A2: I01 | B2: Approver roster incomplete | C2: Country HR lead steps for several jurisdictions and the delegates for Regional HR review have no confirmed incumbent, so the chains cannot be tested end to end before M03. | D2: High | E2: HR Program Manager | F2: Regional HR leads confirm a primary and a delegate for every country step; PMO runs the test submission as soon as the roster is complete. | G2: 46323 | H2: Open
A3: I02 | B3: Current documents spread across many locations | C3: Existing policies and procedures sit in intranet pages, the HRIS document library, country shared drives and email, with no index, which blocks the current-state rating needed for the baseline (M04). | D3: High | E3: HR Program Manager | F3: Run a two-week document sweep with each workstream and region and load every version found into Atlas against its item. | G3: 46330 | H3: Open
A4: I03 | B4: No agreed owner for deemed export controls | C4: Trade Compliance and Talent Acquisition each expect the other to own the export-control role flag and the start-date gate, so these semiconductor items have no owner for the baseline. | D4: High | E4: Director, Talent Acquisition Operations | F4: Bring a proposed RACI to the steering committee for decision, with Trade Compliance accountable for license determinations. | G4: 46318 | H4: Open
A5: I04 | B5: Translation vendor not under contract | C5: Procurement needs 4 to 6 weeks for a new vendor, but Wave 1 needs its first translated drafts in mid-January 2027. | D5: Medium | E5: HR Change and Communications lead | F5: Use the current vendor under its existing agreement for Wave 1 while procurement runs, and agree the glossary and turnaround in writing. | G5: 46339 | H5: Open
A6: I05 | B6: Local counsel not engaged in Taiwan and Vietnam | C6: Wave 1 includes a Taiwan work rules amendment and a Vietnam internal labour regulations registration, and neither country has engaged local counsel. | D6: Medium | E6: Employment counsel | F6: Engage local counsel in both countries on a fixed-fee bundle covering the work rules filing, the ILR dossier and Wave 1 addenda. | G6: 46346 | H6: Open

Sheet Assumptions
A1: ID | B1: Assumption | C1: Owner | D1: Validate by
A2: A01 | B2: The 438 library items (57 policies, 97 processes, 284 legal obligations) are the full scope; new items enter only through change control. | C2: HR Program Manager | D2: 46332
A3: A02 | B3: Workstream leads and regional HR leads can give at least 20% of their time from kickoff to 13 Aug 2027, with the time protected in the charter. | C3: Chief People Officer | D3: 46318
A4: A03 | B4: Employment counsel, with a local counsel panel, can review 25 to 30 items a week at the Wave 1 peak. | C4: Employment counsel | D4: 46332
A5: A04 | B5: Whether an elected works council exists at each German establishment is confirmed in Mobilize; where none exists, German items skip policy chain step s5 with a note. | C5: Country HR lead, Germany | D5: 46325
A6: A05 | B6: Darwinbox stays the HRIS of record for the whole program, and the HRIS team can deliver configuration changes in monthly release windows. | C6: Director, HRIS and People Analytics | D6: 46332
A7: A06 | B7: Headcount thresholds that drive local duties are confirmed per entity and site, for example Taiwan 30+ (work rules filing), Israel 25+ (sexual harassment bylaw), Vietnam 10+ (registered internal labour regulations) and India 10+, 20+ and 300+ (POSH committee, grievance committee, standing orders). | C7: Regional HR leads (Americas, EMEA, APAC) | D7: 46332
A8: A07 | B8: One translation vendor can cover German, Hebrew, Simplified and Traditional Chinese, Vietnamese, Kannada, Telugu and Spanish within 10 business days per batch. | C8: HR Change and Communications lead | D8: 46339
A9: A08 | B9: Every employee, including lab and operations staff, has a corporate login that lets them read published policies and complete acknowledgments. | C9: Director, HRIS and People Analytics | D9: 46346
A10: A09 | B10: China and Vietnam entities have union or employee representative structures able to run consultation in January 2027. | C10: Regional HR lead (APAC) | D10: 46346
A11: A10 | B11: Internal Audit accepts Atlas approval records and published versions as evidence for SOX-relevant HR controls. | C11: HR Program Manager | D11: 46367
A12: A11 | B12: No reorganisation, acquisition or reduction in force during the program year is large enough to require re-sequencing the waves. | C12: Chief People Officer | D12: 46430

Sheet Decisions
A1: ID | B1: Decision | C1: Detail | D1: Owner | E1: Status | F1: Due
A2: D01 | B2: Policy repository of record | C2: Atlas is the single repository of record for every policy, process and obligation, with version history and approvals. Intranet pages and HRIS links point to the Atlas published version, and local copies are retired at Go live. Where a local text is the binding version (China handbook, Taiwan work rules, Vietnam internal labour regulations, Germany works agreements), Atlas holds it as the country document. | D2: Chief People Officer | E2: Proposed | F2: 46318
A3: D02 | B3: Global policy with country addenda | C3: Each policy is one global document with a country addendum wherever local law adds or changes requirements. Separate local documents are used only where the law requires them: Germany works agreements, the China employee handbook, Taiwan work rules, Vietnam internal labour regulations, India standing orders or service rules and the Israel sexual harassment prevention bylaw. | D3: Employment counsel | E3: Proposed | F3: 46318
A4: D03 | B4: Approval chain design | C4: Five role-based chains: global policy (6 steps), process document (4), legal obligation (3), public company and semiconductor control (3) and project document (3). Employee representative consultation is an optional policy step recorded with an outcome or a skip note. Every step has a named primary and delegate. | D4: HR Program Manager | E4: Agreed | F4: 46325
A5: D04 | B5: Translation vendor and prevailing language | C5: Select one translation vendor for German, Hebrew, Simplified and Traditional Chinese, Vietnamese, Kannada, Telugu and Spanish, working from an HR and legal glossary. English is the master text except in China, Taiwan and Vietnam, where the local text prevails because courts and authorities rely on it. The Country HR lead signs off each translation. | D5: HR Change and Communications lead | E5: Proposed | F5: 46332
A6: D05 | B6: Wave sequencing method | C6: Rank items by legal, public-company and semiconductor risk, then by current-state rating. Each workstream delivers about 40% of its required items in Wave 1, 35% in Wave 2 and 25% in Wave 3, and best-practice items go to Wave 4. Policies come before the processes, notices and controls that depend on them. | D6: HR Program Manager | E6: Agreed | F6: 46332
A7: D06 | B7: Effective-date convention | C7: Global effective dates fall on the 1st or 15th of a month, at least 10 business days after final approval and never inside a holiday freeze. Where consultation, filing or registration is required (Germany, China, Taiwan, Vietnam), the country addendum states a later local effective date and the policy applies there only from that date. | D7: Employment counsel | E7: Proposed | F7: 46325
A8: D07 | B8: Attestation and acknowledgment tool | C8: Choose between the Darwinbox acknowledgment workflow and a separate attestation platform for wave acknowledgments and the September 2027 global campaign. Criteria: reach to every employee including lab staff, local-language support, acknowledgment records accepted in China and Vietnam, manager reporting and an audit trail. | D8: Director, HRIS and People Analytics | E8: Proposed | F8: 46346
A9: D08 | B9: Document template standard | C9: Policies use the library policy template (T-POLICY) with purpose, scope, policy statements, roles, country addenda, related items, owner and review date. Processes use a map, steps, controls and a RACI. Obligations use the register fields: requirement, owner, cadence, citation and evidence. All documents use plain English, sentence case and roles rather than names. | D9: HR Program Manager | E9: Agreed | F9: 46325
A10: D09 | B10: Item ownership model | C10: Every item has one accountable owner role, one workstream and a backup. Obligations keep the functional owner shown in the register (for example Trade Compliance or Payroll), with the workstream lead as coordinator. | D10: Chief People Officer | E10: Proposed | F10: 46332
A11: D10 | B11: Legal review tiering and local counsel model | C11: Three tiers: full review with local counsel for items with addenda in Germany, Israel, India, Taiwan, China and Vietnam; full in-house review for US and Canada policies; light review for processes without legal content. Local counsel work on fixed-fee bundles per wave. | D11: Employment counsel | E11: Proposed | F11: 46332
A12: D11 | B12: Germany works council approach | C12: If a works council exists, agree one framework works agreement for Atlas with an annex per co-determined topic (conduct, working time and recording, IT and monitoring tools, pay and bonus principles, mobile work) rather than separate agreements per policy, and decide which existing works agreements stay in force. | D12: Regional HR lead (EMEA) | E12: Proposed | F12: 46353
A13: D12 | B13: Evidence standard per stage | C13: Define what closes each stage: current-state record (Discover), template-complete draft (Draft), resolved comment log (Review), approval chain record (Approve), and the published version with its communication, training or posting record, plus consultation minutes, filing receipt or registration where required (Go live). Internal Audit confirms it can sample against this standard. | D13: HR Program Manager | E13: Proposed | F13: 46332
... A15: D14 | B15: Change control for scope and new laws | C15: New items, or major rework caused by a law change, enter the plan only through a change request that shows the impact on wave dates and resourcing. The PMO reviews it and the steering committee decides, using the project document chain. | D15: Chief People Officer | E15: Proposed | F15: 46318

Sheet RACI
A1: Activity | B1: Sponsor | C1: SteerCo | D1: PMO | E1: WS lead | F1: Item owner | G1: Legal | H1: Regional HR | I1: Comms | J1: Internal Audit
A2: Approve charter, scope, budget and governance (M02) | B2: A | C2: R | D2: R | E2: C | F2: I | G2: C | H2: C | I2: I | J2: I
A3: Maintain plan, RAID log and status reporting | B3: I | C3: I | D3: R/A | E3: C | F3: I | G3: C | H3: C | I3: I | J3: I
A4: Configure and test approval chains (M03) | B4: I | C4: I | D4: R/A | E4: C | F4: I | G4: C | H4: C | J4: C
A5: Confirm owners, current-state ratings and waves (M04) | B5: I | C5: C | D5: R | E5: A | F5: R | G5: C | H5: C | I5: I | J5: I
A6: Discover: find current documents and rate gaps | D6: I | E6: C | F6: R/A | G6: C | H6: R
A7: Draft global text in the standard template | D7: I | E7: C | F7: R/A | G7: C | H7: C | I7: I
A8: Draft country addenda and arrange translation | D8: I | E8: I | F8: C | G8: C | H8: R/A | I8: I
A9: Legal review and local counsel engagement | D9: I | E9: I | F9: C | G9: R/A | H9: C
A10: Employee-representative consultation and local filings | C10: I | D10: I | E10: I | F10: C | G10: C | H10: R/A | I10: C
A11: Final approval of global policies and effective dates | B11: A | C11: I | D11: I | E11: R | F11: R | G11: R | H11: R | I11: I
A12: Publish approval of process documents (Head of HR Operations) | D12: I | E12: R/A | F12: R | G12: C | H12: C | I12: I | J12: C
A13: Sign-off of legal obligation evidence | D13: I | E13: I | F13: R | G13: A | H13: R
A14: Approval of public-company and semiconductor controls (General Counsel or delegate) | C14: I | D14: I | E14: C | F14: R | G14: A | J14: C
A15: Publish, communicate and mark items live | D15: R | E15: C | F15: A | G15: I | H15: R | I15: R
A16: Communications calendar, manager toolkits and training | B16: I | D16: C | E16: C | F16: C | G16: I | H16: C | I16: R/A
A17: Global attestation campaign (M15) | B17: C | C17: I | D17: R | E17: I | F17: C | G17: C | H17: R | I17: A | J17: I
A18: Approve change requests outside PMO tolerance | B18: C | C18: A | D18: R | E18: C | F18: I | G18: C | H18: C | I18: I
A19: Audit readiness review (M16) | B19: I | C19: I | D19: R | E19: C | F19: C | G19: C | J19: R/A
A20: Handover to business as usual (M17) | B20: I | C20: I | D20: A | E20: R | F20: R | H20: C | I20: I
A21: Close-out report and lessons learned (M18) | B21: A | C21: R | D21: R | E21: C | F21: I | G21: C | H21: C | I21: C | J21: C

Sheet Approval chains
A1: Chain | B1: Applies to | C1: Step | D1: Step name | E1: Role | F1: Must sign | G1: Optional | H1: Guidance | I1: Named approvers
A2: Global policy | B2: Policies | C2: 1 | D2: Owner sign-off | E2: Policy owner | F2: Any | G2: No | H2: Confirms the draft is complete, uses the standard template and has every country addendum.
A3: Global policy | B3: Policies | C3: 2 | D3: Workstream review | E3: Workstream lead | F3: Any | G3: No | H3: Checks consistency with related policies and processes.
A4: Global policy | B4: Policies | C4: 3 | D4: Legal review | E4: Employment counsel | F4: Any | G4: No | H4: Confirms legal requirements are met in every jurisdiction; engages local counsel where needed.
A5: Global policy | B5: Policies | C5: 4 | D5: Regional HR review | E5: Regional HR leads (Americas, EMEA, APAC) | F5: All | G5: No | H5: Each region confirms the addenda are workable and flags consultation or filing needs.
A6: Global policy | B6: Policies | C6: 5 | D6: Employee representative consultation | E6: Country HR lead | F6: Any | G6: Yes | H6: Required where works councils or employee representatives have rights (Germany, China, Vietnam, Taiwan filings). Record the outcome; skip with a note where not needed.
A7: Global policy | B7: Policies | C7: 6 | D7: Final approval | E7: Chief People Officer | F7: Any | G7: No | H7: Approves publication and the effective date.
A8: Process document | B8: Processes | C8: 1 | D8: Process owner sign-off | E8: Process owner | F8: Any | G8: No | H8: Confirms the flow matches how work is actually done, including exceptions.
A9: Process document | B9: Processes | C9: 2 | D9: Workstream review | E9: Workstream lead | F9: Any | G9: No | H9: Checks hand-offs with other processes and the governing policy.
A10: Process document | B10: Processes | C10: 3 | D10: Control review | E10: Internal Audit or SOX PMO | F10: Any | G10: Yes | H10: Required when the process contains a key or SOX-relevant control.
A11: Process document | B11: Processes | C11: 4 | D11: Publish approval | E11: Head of HR Operations | F11: Any | G11: No | H11: Approves publication and confirms systems and training are ready.
A12: Legal obligation | B12: Filings, notices, programs, trainings, records and committees | C12: 1 | D12: Owner sign-off | E12: Item owner | F12: Any | G12: No | H12: Confirms the obligation is met and evidence is filed.
A13: Legal obligation | B13: Filings, notices, programs, trainings, records and committees | C13: 2 | D13: Legal and compliance review | E13: Employment counsel or Compliance | F13: Any | G13: No | H13: Confirms the evidence satisfies the requirement and the next due date is set.
... A20: Project document | B20: Charter, plan and change requests | C20: 3 | D20: Sponsor approval | E20: Chief People Officer | F20: Any | G20: No | H20: Final approval.

Sheet Country gates
A1: Jurisdiction | B1: Consultation | C1: Filing or registration | D1: Language | E1: Lead time | F1: Notes | G1: Verify
A2: United States — Federal (+ multi-state) | B2: None required: there are no works councils. Check every handbook rule against NLRA Section 7: under Stericycle (still binding), confidentiality, social media, recording, civility and media-contact rules must be narrowly tailored with a savings clause, whether or not a union exists. | C2: None for HR policies. Separate public-company duties: the Code of conduct must be publicly available with executive waivers disclosed (Nasdaq), and insider trading policies are filed with SEC reports or their absence explained. | D2: English. No federal language mandate for handbooks; English-only rules need business necessity. State rules decide translated notices. | E2: 1 to 2 weeks after final approval to publish, set up acknowledgment and brief managers. No statutory waiting period. | F2: Federal floor only; the work state drives most addenda. Where a handbook exists it must describe FMLA rights (50+ employees). Evidence is the handbook acknowledgment with state addenda.
A3: California | B3: None (NLRA only, no works councils). The Workplace Violence Prevention Plan must be developed with employee involvement. The SB 399 captive-audience ban is preliminarily enjoined. | C3: None for HR policies. The annual CRD pay data report (100+ employees, due the second Wednesday of May) is a separate obligation. | D3: Translate EEO and harassment policies into any language spoken by 10% or more of a facility's workforce (2 CCR 11023); Spanish is the likely trigger at some sites, depending on site workforce data (verify). Give the LC 2810.5 notice in the language normally used with the employee and the SB 294 notice in the employee's usual work language where a state template exists. | E3: 2 to 4 weeks, mainly for translation and acknowledgment. The Workplace Know Your Rights notice is due at hire and by 1 Feb each year. | F3: Handbooks must describe CFRA and PDL rights (5+ employees). No non-competes or non-California law or forum clauses. Watch CCPA automated decision-making duties from 1 Jan 2027 and SB 947 (operative 1 Jul 2027 if signed).
A4: Colorado | B4: None (NLRA only, no works councils). | C4: None for HR policies. State EEO-1 filing rules (HB 26-1207) are expected late 2026, with a first filing in 2027. | D4: Paid sick leave (HFWA) notice in English and any language spoken by 5% or more of the workforce; FAMLI notices in English and Spanish. | E4: 2 to 3 weeks, mainly for Spanish and other translations. Refresh COMPS and PAY CALC figures in the Colorado addendum each 1 January. | F4: Colorado addenda cover the POWR Act harassment program and complaint repository, job posting and promotion notices, biometric and data-disposal policies. SB 26-189 AI notices apply from 1 Jan 2027 to tools that materially influence employment decisions.
A5: North Carolina | B5: None. Right-to-work state; the NLRA governs and there are no consultation duties. | C5: None for HR policies. | D5: No statutory language requirement. NCDOL publishes Spanish posters; giving wage notices in a language the employee understands is best practice. | E5: Wage-related policies (PTO, bonus, commission, deductions) must be given to employees in writing or posted before they can be enforced, and any change that reduces wages or wage benefits needs written notice at least one full pay period ahead. Plan 2 to 3 weeks. | F5: State vacation forfeiture terms in writing. NC session laws often take effect on 1 Jul, 1 Oct or 1 Dec.
A6: Texas | B6: None. Right-to-work state; the NLRA governs and there are no consultation duties. | C6: None for HR policies. | D6: Workers' compensation coverage notices posted in English, Spanish and any other language common to the workforce. Deduction authorizations and policies in a language the employee understands. | E6: 1 to 2 weeks. Vacation, holiday, sick and severance pay are owed only under a written agreement or policy, so publish the policy before relying on its terms. | F6: Texas addenda cover the Payday Law, CUBI biometric notice, firearms in parking areas and the ban on COVID-19 vaccine mandates. The 2027 regular session runs Jan to Jun, and most new laws take effect 1 Sep 2027, inside Wave 4.
A7: Washington State | B7: None (NLRA, no works councils). Mandatory meetings on unionization are banned (RCW 49.44.250). Locations with 11+ employees on the same shift need an elected safety committee; involve it in Accident Prevention Program changes. | C7: None for HR policies. | D7: No translation mandate for contracts or handbooks. I-9 inspection notices (from 1 Oct 2026) go out in English and the five most common other languages in Washington. | E7: 1 to 2 weeks. New laws usually take effect about 90 days after the session and rates change each 1 January; the noncompete ban starts 30 June 2027. | F7: Seattle addenda cover Paid Sick and Safe Time, SMC 14.04 protected classes and the commuter benefit. Agreements need Silenced No More carve-outs.
A8: Canada: Toronto (Ontario) and Vancouver (British Columbia) | B8: None outside unionized workplaces. The Ontario workplace harassment program is developed with the joint health and safety committee or representative (JHSC at 20+ workers); BC has a joint committee at 20+ workers. | C8: None for HR policies. | D8: English for Ontario and BC. French only if there are Quebec-based employees, including remote staff: then contracts, policies and written communications must be in French (Bill 96), and 25+ Quebec employees triggers OQLF registration. | E8: Ontario employers with 25+ employees on 1 Jan need disconnecting-from-work and electronic monitoring policies by 1 March, with copies to employees within 30 days. Harassment, violence and health and safety policies are posted and reviewed annually. Plan 3 to 5 weeks. | F8: Toronto and Vancouver addenda. AODA accessibility policies must be documented at 50+ employees. BC requires a bullying and harassment policy with reporting and investigation procedures.
